<?xml version="1.0"?>
<robot name="arduinobot" xmlns:xacro="http://www.ros.org/wiki/xacro">
    
    <xacro:property name="PI" value="3.14159" />
    <xacro:property name="effort" value="30" />
    <xacro:property name="velocity" value="10" />


        <link name="world" />

        <link name = "base_link">
            <visual>
                <origin rpy="0 0 0" xyz="-0.5 -0.5 0" />
                <geometry>
                    <mesh filename="package://arduinobot_description/meshes/basement.stl" scale="0.01 0.01 0.01" />
                </geometry>
            </visual>   
        </link>

        <joint name="virtual_joint" type="fixed">
            <parent link="world" />
            <child link="base_link" />

            <origin rpy="0 0 0" xyz="0 0 0" />
        </joint>

        <link name="base_plate">
            <visual>
                <origin rpy="0 0 0" xyz="-0.39 -0.39 -0.56" />
                <geometry>
                    <mesh filename="package://arduinobot_description/meshes/base_plate.stl" scale="0.01 0.01 0.01" />
                </geometry>
            </visual>
        </link>

        <joint name="base_link_base_plate_joint_1" type="revolute">
            <parent link="base_link" />
            <child link="base_plate" />
            <axis xyz="0 0 1" />
            <origin rpy="0 0 0" xyz="0 0 0.307" />
            <limit lower="-${PI/2}" upper="${PI/2}" effort="${effort}" velocity="${velocity}" />
        </joint>

        <link name="forward_drive_arm">
            <visual>
                <origin rpy="0 -${PI/2} ${PI/2}" xyz="0.19 0.06 -0.08" />
                <geometry>
                    <mesh filename="package://arduinobot_description/meshes/forward_drive_arm.stl" scale="0.01 0.01 0.01" />
                </geometry>
            </visual>    
        </link> 
        <joint name="base_plate_forward_drive_arm_joint_1" type="revolute">
            <parent link="base_plate" />
            <child link="forward_drive_arm" />
            <axis xyz="1 0 0" />
            <origin rpy="0 0 0" xyz="-0.02 0 0.35" />
            <limit lower="-${PI/2}" upper="${PI/2}" effort="${effort}" velocity="${velocity}" />
        </joint>

        <link name="horizontal_arm">
            <visual>
                <origin rpy="${PI/2} 0 ${PI/2}" xyz="-0.03 -0.4 -0.06" />
                <geometry>
                    <mesh filename="package://arduinobot_description/meshes/horizontal_arm.stl" scale="0.01 0.01 0.01" />
                </geometry>
            </visual>   
        </link>

        <joint name="forward_drive_arm_horizontal_arm_joint_1" type="revolute">
            <parent link="forward_drive_arm" />
            <child link="horizontal_arm" />
            <axis xyz="1 0 0" />
            <origin rpy="0 0 0" xyz="0 0 0.8" />
            <limit lower="-${PI/2}" upper="${PI/2}" effort="${effort}" velocity="${velocity}" />
        </joint>

        <link name="claw_support">
            <visual>
                <origin rpy="0 0 ${PI/2}" xyz="0 -0.05 -0.15" />
                <geometry>
                    <mesh filename="package://arduinobot_description/meshes/claw_support.stl" scale="0.01 0.01 0.01" />
                </geometry>
            </visual>
        </link>

        <joint name="horizontal_arm_claw_support_joint_1" type="fixed">
            <parent link="horizontal_arm" />
            <child link="claw_support" />
            <origin rpy="0 0 0" xyz="0 0.82 0" />
        </joint>

        <link name="gripper_right">
            <visual>
                <origin rpy="0 0 -${PI/2}" xyz="-0.1 0.5 -0.1" />
                <geometry>
                    <mesh filename="package://arduinobot_description/meshes/right_finger.stl" scale="0.01 0.01 0.01" />
                </geometry>
            </visual>
        </link>

        <link name="gripper_left">
            <visual>
                <origin rpy="0 0 -${PI/2}" xyz="-0.04 0.5 -0.1" />
                <geometry>
                    <mesh filename="package://arduinobot_description/meshes/left_finger.stl" scale="0.01 0.01 0.01" />
                </geometry>
            </visual>
        </link>

        <joint name="claw_support_to_gripper_right_joint_1" type="revolute">
            <parent link="claw_support" />
            <child link="gripper_right" />
            <axis xyz="0 0 1" />
            <origin rpy="0 0 0" xyz="-0.04 0.13 -0.1" />
            <limit lower="-${PI/2}" upper="0.0" effort="${effort}" velocity="${velocity}" />
        </joint>

        
        <joint name="claw_support_to_gripper_left_joint_1" type="revolute">
            <parent link="claw_support" />
            <child link="gripper_left" />
            <axis xyz="0 0 1" />
            <origin rpy="0 0 0" xyz="-0.22 0.13 -0.1" />
            <mimic joint="claw_support_to_gripper_right_joint_1" multiplier="-1" />
            <limit lower="0.0" upper="${PI/2}" effort="${effort}" velocity="${velocity}" />
        </joint>
</robot>